{"CVE Code": "CVE-2022-47515", "Description": "An issue was discovered in drachtio-server before 0.8.20. It allows remote attackers to cause a denial of service (daemon crash) via a long message in a TCP request that leads to std::length_error.", "NVD Link": "https://nvd.nist.gov/vuln/detail/CVE-2022-47515", "Vulnerability Categories": "Denial of service", "Affected Products": "\nDrachtio\u00bbDrachtio-serverVersions  before (<) 0.8.20cpe:2.3:a:drachtio:drachtio-server:*:*:*:*:*:*:*:*Matching versions", "EPSS Score": "0.17% Probability of exploitation activity in the next 30 days\n~ 54 % Percentile, the proportion of vulnerabilities that are scored at or less", "EPSS History": "\n #  Date  Old EPSS Score  New EPSS Score  Delta (New - Old) \n 1  2024-12-17  0.18%  0.17%  -0.01 \n 2  2024-07-10  0.17%  0.18%  +0.01 \n 3  2024-05-30  0.16%  0.17%  +0.02 \n 4  2024-01-19  0.14%  0.16%  +0.02 \n 5  2023-12-24  0.11%  0.14%  +0.03 \n 6  2023-11-17  0.09%  0.11%  +0.01 \n 7  2023-03-07  1.06%  0.09%  -0.96 ", "CVSS Scores": "7.5", "CWE": [], "Reference": [{"ref_link": "https://github.com/drachtio/drachtio-server/commit/4cf9fe2c420b86c16442215d449d40be777c1911", "ref_desc": "bugfix (#245) - long incoming message crashes server \u00b7 drachtio/drachtio-server@4cf9fe2 \u00b7 GitHubPatch;Third Party Advisory", "ref_cve_link": "N/A"}, {"ref_link": "https://github.com/drachtio/drachtio-server/issues/245", "ref_desc": "terminate called after throwing an instance of 'std::length_error' \u00b7 Issue #245 \u00b7 drachtio/drachtio-server \u00b7 GitHubExploit;Third Party Advisory", "ref_cve_link": "N/A"}]}