{"CVE Code": "CVE-2020-35917", "Description": "An issue was discovered in the pyo3 crate before 0.12.4 for Rust. There is a reference-counting error and use-after-free in From<Py<T>>.", "NVD Link": "https://nvd.nist.gov/vuln/detail/CVE-2020-35917", "Vulnerability Categories": "Memory Corruption", "Affected Products": "\nPyo3 Project\u00bbPyo3\u00bbForRustVersions  before (<) 0.12.4cpe:2.3:a:pyo3_project:pyo3:*:*:*:*:*:rust:*:*Matching versions", "EPSS Score": "0.04% Probability of exploitation activity in the next 30 days\n~ 11 % Percentile, the proportion of vulnerabilities that are scored at or less", "EPSS History": "\n #  Date  Old EPSS Score  New EPSS Score  Delta (New - Old) \n 1  2023-03-07  0.89%  0.04%  -0.84 ", "CVSS Scores": "2.1", "CWE": [{"CWE_ID": "CWE-416 Use After Free", "CWE_link": "/cwe-details/416/Use-After-Free.html"}], "Reference": [{"ref_link": "https://rustsec.org/advisories/RUSTSEC-2020-0074.html", "ref_desc": "RUSTSEC-2020-0074: pyo3: Reference counting error in `From<Py<T>>` \u203a RustSec Advisory DatabaseExploit;Patch;Third Party Advisory", "ref_cve_link": "N/A"}]}