{"CVE Code": "CVE-2015-5145", "Description": "validators.URLValidator in Django 1.8.x before 1.8.3 allows remote attackers to cause a denial of service (CPU consumption) via unspecified vectors.", "NVD Link": "https://nvd.nist.gov/vuln/detail/CVE-2015-5145", "Vulnerability Categories": "Denial of service", "Affected Products": "\nDjangoproject\u00bbDjango\u00bbVersion:1.8.0cpe:2.3:a:djangoproject:django:1.8.0:*:*:*:*:*:*:*Matching versions\nDjangoproject\u00bbDjango\u00bbVersion:1.8.1cpe:2.3:a:djangoproject:django:1.8.1:*:*:*:*:*:*:*Matching versions\nDjangoproject\u00bbDjango\u00bbVersion:1.8.2cpe:2.3:a:djangoproject:django:1.8.2:*:*:*:*:*:*:*Matching versions", "EPSS Score": "0.76% Probability of exploitation activity in the next 30 days\n~ 81 % Percentile, the proportion of vulnerabilities that are scored at or less", "EPSS History": "\n #  Date  Old EPSS Score  New EPSS Score  Delta (New - Old) \n 1  2024-12-17  0.87%  0.76%  -0.11 \n 2  2023-03-07  1.21%  0.87%  -0.34 ", "CVSS Scores": "7.8", "CWE": [{"CWE_ID": "CWE-399", "CWE_link": "/cwe-details/399/cwe.html"}], "Reference": [{"ref_link": "https://security.gentoo.org/glsa/201510-06", "ref_desc": "Django: Multiple vulnerabilities (GLSA 201510-06) \u2014 Gentoo securityCVEs referencing this url", "ref_cve_link": "https://www.cvedetails.com/reference-url-info/5d5Iiryb9OLnCO0OLrXHCcSxhfo.html"}, {"ref_link": "http://www.securitytracker.com/id/1032820", "ref_desc": "Django Bugs Let Remote Users Deny Service and Conduct HTTP/Header Response Splitting Attacks - SecurityTrackerCVEs referencing this url", "ref_cve_link": "https://www.cvedetails.com/reference-url-info/jMagxY8ovfDXjpFmR1Oj59ml25Q.html"}, {"ref_link": "https://www.djangoproject.com/weblog/2015/jul/08/security-releases/", "ref_desc": "Security releases issued: 1.8.3, 1.7.9, 1.4.21 | Weblog | DjangoVendor AdvisoryCVEs referencing this url", "ref_cve_link": "https://www.cvedetails.com/reference-url-info/kPYSYEeJeoriIlPYwWAO-j6tUbo.html"}, {"ref_link": "http://www.securityfocus.com/bid/75691", "ref_desc": "Django CVE-2015-5145 Denial of Service Vulnerability", "ref_cve_link": "N/A"}]}