{"CVE Code": "CVE-2023-29824", "Description": "A use-after-free issue was discovered in Py_FindObjects() function in SciPy versions prior to 1.8.0. NOTE: the vendor and discoverer indicate that this is not a security issue.", "NVD Link": "https://nvd.nist.gov/vuln/detail/CVE-2023-29824", "Vulnerability Categories": "Memory Corruption", "Affected Products": "\nScipy\u00bbScipyVersions  before (<) 1.8.0cpe:2.3:a:scipy:scipy:*:*:*:*:*:*:*:*Matching versions", "EPSS Score": "0.16% Probability of exploitation activity in the next 30 days\n~ 53 % Percentile, the proportion of vulnerabilities that are scored at or less", "EPSS History": "\n #  Date  Old EPSS Score  New EPSS Score  Delta (New - Old) \n 1  2024-08-07  0.14%  0.16%  +0.02 \n 2  2024-07-12  0.08%  0.14%  +0.06 \n 3  2024-06-05  0.07%  0.08%  +0.02 \n 4  2023-07-18  0.05%  0.07%  +0.02 ", "CVSS Scores": "9.8", "CWE": [{"CWE_ID": "CWE-416 Use After Free", "CWE_link": "/cwe-details/416/Use-After-Free.html"}], "Reference": [{"ref_link": "https://github.com/scipy/scipy/issues/14713", "ref_desc": "BUG: Potential use-after-free bug in function `Py_FindObjects` \u00b7 Issue #14713 \u00b7 scipy/scipy \u00b7 GitHubExploit;Issue Tracking", "ref_cve_link": "N/A"}, {"ref_link": "https://github.com/scipy/scipy/issues/14713#issuecomment-1629468565", "ref_desc": "BUG: Potential use-after-free bug in function `Py_FindObjects` \u00b7 Issue #14713 \u00b7 scipy/scipy \u00b7 GitHubExploit;Issue Tracking", "ref_cve_link": "N/A"}, {"ref_link": "http://www.square16.org/achievement/cve-2023-29824/", "ref_desc": "CVE-2023-29824 \u2013 SQUARE GroupProduct", "ref_cve_link": "N/A"}, {"ref_link": "https://github.com/scipy/scipy/pull/15013", "ref_desc": "MAINT: Fix use-after-free bug in Py_FindObjects by AnirudhDagar \u00b7 Pull Request #15013 \u00b7 scipy/scipy \u00b7 GitHubPatch", "ref_cve_link": "N/A"}]}